Microsoft Windows [Version 10.0.19044.1949]
(c) Microsoft Corporation. All rights reserved.

D:\b6>Python -m Venv mt
C:\ProgramData\Anaconda3\python.exe: No module named Venv

D:\b6>Python -m venv mt 

D:\b6>cd mt 

D:\b6\mt>Scripts\activate

(mt) D:\b6\mt>cd..

(mt) D:\b6>cd mt

(mt) D:\b6\mt>pip install djangp
ERROR: Could not find a version that satisfies the requirement djangp (from versions: none)
ERROR: No matching distribution found for djangp
WARNING: You are using pip version 20.1.1; however, version 25.0.1 is available.
You should consider upgrading via the 'd:\b6\mt\scripts\python.exe -m pip install --upgrade pip' command.

(mt) D:\b6\mt>pip install django
Collecting django
  Downloading django-4.2.23-py3-none-any.whl (8.0 MB)
     |████████████████████████████████| 8.0 MB 2.2 MB/s
Collecting backports.zoneinfo; python_version < "3.9"
  Using cached backports.zoneinfo-0.2.1-cp38-cp38-win_amd64.whl (38 kB)
Collecting sqlparse>=0.3.1
  Downloading sqlparse-0.5.3-py3-none-any.whl (44 kB)
     |████████████████████████████████| 44 kB ...
Collecting tzdata; sys_platform == "win32"
  Downloading tzdata-2025.2-py2.py3-none-any.whl (347 kB)
     |████████████████████████████████| 347 kB 6.4 MB/s
Collecting asgiref<4,>=3.6.0
  Using cached asgiref-3.8.1-py3-none-any.whl (23 kB)
Collecting typing-extensions>=4; python_version < "3.11"
  Downloading typing_extensions-4.13.2-py3-none-any.whl (45 kB)
     |████████████████████████████████| 45 kB ...
Installing collected packages: backports.zoneinfo, sqlparse, tzdata, typing-extensions, asgiref, django
Successfully installed asgiref-3.8.1 backports.zoneinfo-0.2.1 django-4.2.23 sqlparse-0.5.3 typing-extensions-4.13.2 tzdata-2025.2
WARNING: You are using pip version 20.1.1; however, version 25.0.1 is available.
You should consider upgrading via the 'd:\b6\mt\scripts\python.exe -m pip install --upgrade pip' command.

(mt) D:\b6\mt>cd..

(mt) D:\b6>Python -m django startproject p1

(mt) D:\b6>cd p1

(mt) D:\b6\p1>Python manage.py startapp app1

(mt) D:\b6\p1>
(mt) D:\b6\p1>Python manage.py runserver    
Watching for file changes with StatReloader
Performing system checks...

System check identified no issues (0 silenced).

You have 18 unapplied migration(s). Your project may not work properly until you apply the migrations for app(s): admin, auth, contenttypes, sessions.
Run 'python manage.py migrate' to apply them.
July 02, 2025 - 09:44:58
Django version 4.2.23, using settings 'p1.settings'
Starting development server at http://127.0.0.1:8000/
Quit the server with CTRL-BREAK.

[02/Jul/2025 09:45:40] "GET / HTTP/1.1" 200 10664
[02/Jul/2025 09:45:40] "GET / HTTP/1.1" 200 10664
Not Found: /favicon.ico
[02/Jul/2025 09:45:41] "GET /favicon.ico HTTP/1.1" 404 2106

(mt) D:\b6\p1>Python manage.py runserver 7000
Watching for file changes with StatReloader
Performing system checks...

System check identified no issues (0 silenced).

You have 18 unapplied migration(s). Your project may not work properly until you apply the migrations for app(s): admin, auth, contenttypes, sessions.
Run 'python manage.py migrate' to apply them.
July 02, 2025 - 09:47:23
Django version 4.2.23, using settings 'p1.settings'
Starting development server at http://127.0.0.1:7000/
Quit the server with CTRL-BREAK.

[02/Jul/2025 09:47:31] "GET / HTTP/1.1" 200 10664
Not Found: /favicon.ico
[02/Jul/2025 09:47:31] "GET /favicon.ico HTTP/1.1" 404 2106
D:\b6\p1\p1\settings.py changed, reloading.
Watching for file changes with StatReloader
Performing system checks...

System check identified no issues (0 silenced).

You have 18 unapplied migration(s). Your project may not work properly until you apply the migrations for app(s): admin, auth, contenttypes, sessions.
Run 'python manage.py migrate' to apply them.
July 02, 2025 - 09:51:00
Django version 4.2.23, using settings 'p1.settings'
Starting development server at http://127.0.0.1:7000/
Quit the server with CTRL-BREAK.

D:\b6\p1\p1\urls.py changed, reloading.
Watching for file changes with StatReloader
Performing system checks...

Exception in thread django-main-thread:
Traceback (most recent call last):
  File "C:\ProgramData\Anaconda3\lib\threading.py", line 932, in _bootstrap_inner
    self.run()
  File "C:\ProgramData\Anaconda3\lib\threading.py", line 870, in run
    self._target(*self._args, **self._kwargs)
  File "D:\b6\mt\lib\site-packages\django\utils\autoreload.py", line 64, in wrapper
    fn(*args, **kwargs)
  File "D:\b6\mt\lib\site-packages\django\core\management\commands\runserver.py", line 133, in inner_run
    self.check(display_num_errors=True)
  File "D:\b6\mt\lib\site-packages\django\core\management\base.py", line 485, in check
    all_issues = checks.run_checks(
  File "D:\b6\mt\lib\site-packages\django\core\checks\registry.py", line 88, in run_checks
    new_errors = check(app_configs=app_configs, databases=databases)
  File "D:\b6\mt\lib\site-packages\django\core\checks\urls.py", line 42, in check_url_namespaces_unique
    all_namespaces = _load_all_namespaces(resolver)
  File "D:\b6\mt\lib\site-packages\django\core\checks\urls.py", line 61, in _load_all_namespaces
    url_patterns = getattr(resolver, "url_patterns", [])
  File "D:\b6\mt\lib\site-packages\django\utils\functional.py", line 57, in __get__
    res = instance.__dict__[self.name] = self.func(instance)
  File "D:\b6\mt\lib\site-packages\django\urls\resolvers.py", line 715, in url_patterns
    patterns = getattr(self.urlconf_module, "urlpatterns", self.urlconf_module)
  File "D:\b6\mt\lib\site-packages\django\utils\functional.py", line 57, in __get__
    res = instance.__dict__[self.name] = self.func(instance)
  File "D:\b6\mt\lib\site-packages\django\urls\resolvers.py", line 708, in urlconf_module
    return import_module(self.urlconf_name)
  File "C:\ProgramData\Anaconda3\lib\importlib\__init__.py", line 127, in import_module
    return _bootstrap._gcd_import(name[level:], package, level)
  File "<frozen importlib._bootstrap>", line 1014, in _gcd_import
  File "<frozen importlib._bootstrap>", line 991, in _find_and_load
  File "<frozen importlib._bootstrap>", line 975, in _find_and_load_unlocked
  File "<frozen importlib._bootstrap>", line 671, in _load_unlocked
  File "<frozen importlib._bootstrap_external>", line 783, in exec_module
  File "<frozen importlib._bootstrap>", line 219, in _call_with_frames_removed
  File "D:\b6\p1\p1\urls.py", line 19, in <module>
    from app1 import views
  File "D:\b6\p1\app1\views.py", line 5
    def B6(request)
                  ^
SyntaxError: invalid syntax

(mt) D:\b6\p1>Python manage.py runserver 7000 
Watching for file changes with StatReloader
Performing system checks...

Exception in thread django-main-thread:
Traceback (most recent call last):
  File "C:\ProgramData\Anaconda3\lib\threading.py", line 932, in _bootstrap_inner
    self.run()
  File "C:\ProgramData\Anaconda3\lib\threading.py", line 870, in run
    self._target(*self._args, **self._kwargs)
  File "D:\b6\mt\lib\site-packages\django\utils\autoreload.py", line 64, in wrapper
    fn(*args, **kwargs)
  File "D:\b6\mt\lib\site-packages\django\core\management\commands\runserver.py", line 133, in inner_run
    self.check(display_num_errors=True)
  File "D:\b6\mt\lib\site-packages\django\core\management\base.py", line 485, in check
    all_issues = checks.run_checks(
  File "D:\b6\mt\lib\site-packages\django\core\checks\registry.py", line 88, in run_checks
    new_errors = check(app_configs=app_configs, databases=databases)
  File "D:\b6\mt\lib\site-packages\django\core\checks\urls.py", line 42, in check_url_namespaces_unique
    all_namespaces = _load_all_namespaces(resolver)
  File "D:\b6\mt\lib\site-packages\django\core\checks\urls.py", line 61, in _load_all_namespaces
    url_patterns = getattr(resolver, "url_patterns", [])
  File "D:\b6\mt\lib\site-packages\django\utils\functional.py", line 57, in __get__
    res = instance.__dict__[self.name] = self.func(instance)
  File "D:\b6\mt\lib\site-packages\django\urls\resolvers.py", line 715, in url_patterns
    patterns = getattr(self.urlconf_module, "urlpatterns", self.urlconf_module)
  File "D:\b6\mt\lib\site-packages\django\utils\functional.py", line 57, in __get__
    res = instance.__dict__[self.name] = self.func(instance)
  File "D:\b6\mt\lib\site-packages\django\urls\resolvers.py", line 708, in urlconf_module
    return import_module(self.urlconf_name)
  File "C:\ProgramData\Anaconda3\lib\importlib\__init__.py", line 127, in import_module
    return _bootstrap._gcd_import(name[level:], package, level)
  File "<frozen importlib._bootstrap>", line 1014, in _gcd_import
  File "<frozen importlib._bootstrap>", line 991, in _find_and_load
  File "<frozen importlib._bootstrap>", line 975, in _find_and_load_unlocked
  File "<frozen importlib._bootstrap>", line 671, in _load_unlocked
  File "<frozen importlib._bootstrap_external>", line 783, in exec_module
  File "<frozen importlib._bootstrap>", line 219, in _call_with_frames_removed
  File "D:\b6\p1\p1\urls.py", line 19, in <module>
    from app1 import views
  File "D:\b6\p1\app1\views.py", line 5
    def B6(request)
                  ^
SyntaxError: invalid syntax
D:\b6\p1\app1\views.py changed, reloading.
Watching for file changes with StatReloader
Performing system checks...

System check identified no issues (0 silenced).

You have 18 unapplied migration(s). Your project may not work properly until you apply the migrations for app(s): admin, auth, contenttypes, sessions.
Run 'python manage.py migrate' to apply them.
July 02, 2025 - 09:58:19
Django version 4.2.23, using settings 'p1.settings'
Starting development server at http://127.0.0.1:7000/
Quit the server with CTRL-BREAK.

[02/Jul/2025 09:58:22] "GET / HTTP/1.1" 200 10664
Not Found: /abc
[02/Jul/2025 09:58:35] "GET /abc HTTP/1.1" 404 2082
[02/Jul/2025 09:58:42] "GET / HTTP/1.1" 200 10664
Not Found: /abc
[02/Jul/2025 10:02:22] "GET /abc HTTP/1.1" 404 2082
[02/Jul/2025 10:02:27] "GET /admin HTTP/1.1" 301 0
[02/Jul/2025 10:02:27] "GET /admin/ HTTP/1.1" 302 0
[02/Jul/2025 10:02:27] "GET /admin/login/?next=/admin/ HTTP/1.1" 200 4181
[02/Jul/2025 10:02:28] "GET /static/admin/css/base.css HTTP/1.1" 200 21310
[02/Jul/2025 10:02:28] "GET /static/admin/css/dark_mode.css HTTP/1.1" 200 2929
[02/Jul/2025 10:02:28] "GET /static/admin/js/nav_sidebar.js HTTP/1.1" 200 3063
[02/Jul/2025 10:02:28] "GET /static/admin/css/nav_sidebar.css HTTP/1.1" 200 2694
[02/Jul/2025 10:02:28] "GET /static/admin/css/login.css HTTP/1.1" 200 958
[02/Jul/2025 10:02:28] "GET /static/admin/css/responsive.css HTTP/1.1" 200 18559
[02/Jul/2025 10:02:28] "GET /static/admin/js/theme.js HTTP/1.1" 200 1943
D:\b6\p1\p1\urls.py changed, reloading.
Watching for file changes with StatReloader
Performing system checks...

Exception in thread django-main-thread:
Traceback (most recent call last):
  File "C:\ProgramData\Anaconda3\lib\threading.py", line 932, in _bootstrap_inner
    self.run()
  File "C:\ProgramData\Anaconda3\lib\threading.py", line 870, in run
    self._target(*self._args, **self._kwargs)
  File "D:\b6\mt\lib\site-packages\django\utils\autoreload.py", line 64, in wrapper
    fn(*args, **kwargs)
  File "D:\b6\mt\lib\site-packages\django\core\management\commands\runserver.py", line 133, in inner_run
    self.check(display_num_errors=True)
  File "D:\b6\mt\lib\site-packages\django\core\management\base.py", line 485, in check
    all_issues = checks.run_checks(
  File "D:\b6\mt\lib\site-packages\django\core\checks\registry.py", line 88, in run_checks
    new_errors = check(app_configs=app_configs, databases=databases)
  File "D:\b6\mt\lib\site-packages\django\core\checks\urls.py", line 42, in check_url_namespaces_unique
    all_namespaces = _load_all_namespaces(resolver)
  File "D:\b6\mt\lib\site-packages\django\core\checks\urls.py", line 61, in _load_all_namespaces
    url_patterns = getattr(resolver, "url_patterns", [])
  File "D:\b6\mt\lib\site-packages\django\utils\functional.py", line 57, in __get__
    res = instance.__dict__[self.name] = self.func(instance)
  File "D:\b6\mt\lib\site-packages\django\urls\resolvers.py", line 715, in url_patterns
    patterns = getattr(self.urlconf_module, "urlpatterns", self.urlconf_module)
  File "D:\b6\mt\lib\site-packages\django\utils\functional.py", line 57, in __get__
    res = instance.__dict__[self.name] = self.func(instance)
  File "D:\b6\mt\lib\site-packages\django\urls\resolvers.py", line 708, in urlconf_module
    return import_module(self.urlconf_name)
  File "C:\ProgramData\Anaconda3\lib\importlib\__init__.py", line 127, in import_module
    return _bootstrap._gcd_import(name[level:], package, level)
  File "<frozen importlib._bootstrap>", line 1014, in _gcd_import
  File "<frozen importlib._bootstrap>", line 991, in _find_and_load
  File "<frozen importlib._bootstrap>", line 975, in _find_and_load_unlocked
  File "<frozen importlib._bootstrap>", line 671, in _load_unlocked
  File "<frozen importlib._bootstrap_external>", line 783, in exec_module
  File "<frozen importlib._bootstrap>", line 219, in _call_with_frames_removed
  File "D:\b6\p1\p1\urls.py", line 24, in <module>
    Url=[path('','views.B6'),]
  File "D:\b6\mt\lib\site-packages\django\urls\conf.py", line 89, in _path
    raise TypeError(
TypeError: view must be a callable or a list/tuple in the case of include().

(mt) D:\b6\p1>Python manage.py runserver 7000
Watching for file changes with StatReloader
Performing system checks...

System check identified no issues (0 silenced).

You have 18 unapplied migration(s). Your project may not work properly until you apply the migrations for app(s): admin, auth, contenttypes, sessions.
Run 'python manage.py migrate' to apply them.
July 02, 2025 - 10:06:33
Django version 4.2.23, using settings 'p1.settings'
Starting development server at http://127.0.0.1:7000/
Quit the server with CTRL-BREAK.

[02/Jul/2025 10:06:35] "GET / HTTP/1.1" 200 10
Not Found: /favicon.ico
[02/Jul/2025 10:06:35] "GET /favicon.ico HTTP/1.1" 404 2206
D:\b6\p1\app1\views.py changed, reloading.
Watching for file changes with StatReloader
Performing system checks...

System check identified no issues (0 silenced).

You have 18 unapplied migration(s). Your project may not work properly until you apply the migrations for app(s): admin, auth, contenttypes, sessions.
Run 'python manage.py migrate' to apply them.
July 02, 2025 - 10:08:44
Django version 4.2.23, using settings 'p1.settings'
Starting development server at http://127.0.0.1:7000/
Quit the server with CTRL-BREAK.

D:\b6\p1\p1\urls.py changed, reloading.
Watching for file changes with StatReloader
Performing system checks...

System check identified no issues (0 silenced).

You have 18 unapplied migration(s). Your project may not work properly until you apply the migrations for app(s): admin, auth, contenttypes, sessions.
Run 'python manage.py migrate' to apply them.
July 02, 2025 - 10:09:03
Django version 4.2.23, using settings 'p1.settings'
Starting development server at http://127.0.0.1:7000/
Quit the server with CTRL-BREAK.

[02/Jul/2025 10:09:03] "GET / HTTP/1.1" 200 10
[02/Jul/2025 10:09:10] "GET / HTTP/1.1" 200 10
D:\b6\p1\app1\views.py changed, reloading.
Watching for file changes with StatReloader
Performing system checks...

System check identified no issues (0 silenced).

You have 18 unapplied migration(s). Your project may not work properly until you apply the migrations for app(s): admin, auth, contenttypes, sessions.
Run 'python manage.py migrate' to apply them.
July 02, 2025 - 10:09:21
Django version 4.2.23, using settings 'p1.settings'
Starting development server at http://127.0.0.1:7000/
Quit the server with CTRL-BREAK.

D:\b6\p1\p1\urls.py changed, reloading.
Watching for file changes with StatReloader
Performing system checks...

System check identified no issues (0 silenced).

You have 18 unapplied migration(s). Your project may not work properly until you apply the migrations for app(s): admin, auth, contenttypes, sessions.
Run 'python manage.py migrate' to apply them.
July 02, 2025 - 10:09:23
Django version 4.2.23, using settings 'p1.settings'
Starting development server at http://127.0.0.1:7000/
Quit the server with CTRL-BREAK.

D:\b6\p1\p1\urls.py changed, reloading.
Watching for file changes with StatReloader
Performing system checks...

System check identified some issues:

WARNINGS:
?: (urls.W002) Your URL pattern '/mt' has a route beginning with a '/'. Remove this slash as it is unnecessary. If this pattern is targeted in an include(), ensure the include() pattern has a trailing '/'.

System check identified 1 issue (0 silenced).

You have 18 unapplied migration(s). Your project may not work properly until you apply the migrations for app(s): admin, auth, contenttypes, sessions.
Run 'python manage.py migrate' to apply them.
July 02, 2025 - 10:12:06
Django version 4.2.23, using settings 'p1.settings'
Starting development server at http://127.0.0.1:7000/
Quit the server with CTRL-BREAK.

Not Found: /mt
[02/Jul/2025 10:12:11] "GET /mt HTTP/1.1" 404 2282
D:\b6\p1\p1\urls.py changed, reloading.
Watching for file changes with StatReloader
Performing system checks...

System check identified no issues (0 silenced).

You have 18 unapplied migration(s). Your project may not work properly until you apply the migrations for app(s): admin, auth, contenttypes, sessions.
Run 'python manage.py migrate' to apply them.
July 02, 2025 - 10:12:27
Django version 4.2.23, using settings 'p1.settings'
Starting development server at http://127.0.0.1:7000/
Quit the server with CTRL-BREAK.

[02/Jul/2025 10:12:31] "GET /mt HTTP/1.1" 301 0
[02/Jul/2025 10:12:31] "GET /mt/ HTTP/1.1" 200 2

(mt) D:\b6\p1>Python manage.py startapp app2  

(mt) D:\b6\p1>Python manage.py runserver 7000 
Watching for file changes with StatReloader
Performing system checks...

Exception in thread django-main-thread:
Traceback (most recent call last):
  File "C:\ProgramData\Anaconda3\lib\threading.py", line 932, in _bootstrap_inner
    self.run()
  File "C:\ProgramData\Anaconda3\lib\threading.py", line 870, in run
    self._target(*self._args, **self._kwargs)
  File "D:\b6\mt\lib\site-packages\django\utils\autoreload.py", line 64, in wrapper
    fn(*args, **kwargs)
  File "D:\b6\mt\lib\site-packages\django\core\management\commands\runserver.py", line 133, in inner_run
    self.check(display_num_errors=True)
  File "D:\b6\mt\lib\site-packages\django\core\management\base.py", line 485, in check
    all_issues = checks.run_checks(
  File "D:\b6\mt\lib\site-packages\django\core\checks\registry.py", line 88, in run_checks
    new_errors = check(app_configs=app_configs, databases=databases)
  File "D:\b6\mt\lib\site-packages\django\core\checks\urls.py", line 14, in check_url_config
    return check_resolver(resolver)
  File "D:\b6\mt\lib\site-packages\django\core\checks\urls.py", line 24, in check_resolver
    return check_method()
  File "D:\b6\mt\lib\site-packages\django\urls\resolvers.py", line 494, in check
    for pattern in self.url_patterns:
  File "D:\b6\mt\lib\site-packages\django\utils\functional.py", line 57, in __get__
    res = instance.__dict__[self.name] = self.func(instance)
  File "D:\b6\mt\lib\site-packages\django\urls\resolvers.py", line 715, in url_patterns
    patterns = getattr(self.urlconf_module, "urlpatterns", self.urlconf_module)
  File "D:\b6\mt\lib\site-packages\django\utils\functional.py", line 57, in __get__
    res = instance.__dict__[self.name] = self.func(instance)
  File "D:\b6\mt\lib\site-packages\django\urls\resolvers.py", line 708, in urlconf_module
    return import_module(self.urlconf_name)
  File "C:\ProgramData\Anaconda3\lib\importlib\__init__.py", line 127, in import_module
    return _bootstrap._gcd_import(name[level:], package, level)
  File "<frozen importlib._bootstrap>", line 1014, in _gcd_import
  File "<frozen importlib._bootstrap>", line 991, in _find_and_load
  File "<frozen importlib._bootstrap>", line 975, in _find_and_load_unlocked
  File "<frozen importlib._bootstrap>", line 671, in _load_unlocked
  File "<frozen importlib._bootstrap_external>", line 783, in exec_module
  File "<frozen importlib._bootstrap>", line 219, in _call_with_frames_removed
  File "D:\b6\p1\p1\urls.py", line 25, in <module>
    path('m/',views.B),
AttributeError: module 'app1.views' has no attribute 'B'
D:\b6\p1\p1\urls.py changed, reloading.
Watching for file changes with StatReloader
Performing system checks...

Exception in thread django-main-thread:
Traceback (most recent call last):
  File "C:\ProgramData\Anaconda3\lib\threading.py", line 932, in _bootstrap_inner
    self.run()
  File "C:\ProgramData\Anaconda3\lib\threading.py", line 870, in run
    self._target(*self._args, **self._kwargs)
  File "D:\b6\mt\lib\site-packages\django\utils\autoreload.py", line 64, in wrapper
    fn(*args, **kwargs)
  File "D:\b6\mt\lib\site-packages\django\core\management\commands\runserver.py", line 133, in inner_run
    self.check(display_num_errors=True)
  File "D:\b6\mt\lib\site-packages\django\core\management\base.py", line 485, in check
    all_issues = checks.run_checks(
  File "D:\b6\mt\lib\site-packages\django\core\checks\registry.py", line 88, in run_checks
    new_errors = check(app_configs=app_configs, databases=databases)
  File "D:\b6\mt\lib\site-packages\django\core\checks\urls.py", line 14, in check_url_config
    return check_resolver(resolver)
  File "D:\b6\mt\lib\site-packages\django\core\checks\urls.py", line 24, in check_resolver
    return check_method()
  File "D:\b6\mt\lib\site-packages\django\urls\resolvers.py", line 494, in check
    for pattern in self.url_patterns:
  File "D:\b6\mt\lib\site-packages\django\utils\functional.py", line 57, in __get__
    res = instance.__dict__[self.name] = self.func(instance)
  File "D:\b6\mt\lib\site-packages\django\urls\resolvers.py", line 715, in url_patterns
    patterns = getattr(self.urlconf_module, "urlpatterns", self.urlconf_module)
  File "D:\b6\mt\lib\site-packages\django\utils\functional.py", line 57, in __get__
    res = instance.__dict__[self.name] = self.func(instance)
  File "D:\b6\mt\lib\site-packages\django\urls\resolvers.py", line 708, in urlconf_module
    return import_module(self.urlconf_name)
  File "C:\ProgramData\Anaconda3\lib\importlib\__init__.py", line 127, in import_module
    return _bootstrap._gcd_import(name[level:], package, level)
  File "<frozen importlib._bootstrap>", line 1014, in _gcd_import
  File "<frozen importlib._bootstrap>", line 991, in _find_and_load
  File "<frozen importlib._bootstrap>", line 975, in _find_and_load_unlocked
  File "<frozen importlib._bootstrap>", line 671, in _load_unlocked
  File "<frozen importlib._bootstrap_external>", line 783, in exec_module
  File "<frozen importlib._bootstrap>", line 219, in _call_with_frames_removed
  File "D:\b6\p1\p1\urls.py", line 24, in <module>
    path('',views.B6),
AttributeError: module 'app2.views' has no attribute 'B6'
D:\b6\p1\p1\urls.py changed, reloading.
Watching for file changes with StatReloader
Performing system checks...

Exception in thread django-main-thread:
Traceback (most recent call last):
  File "C:\ProgramData\Anaconda3\lib\threading.py", line 932, in _bootstrap_inner
    self.run()
  File "C:\ProgramData\Anaconda3\lib\threading.py", line 870, in run
    self._target(*self._args, **self._kwargs)
  File "D:\b6\mt\lib\site-packages\django\utils\autoreload.py", line 64, in wrapper
    fn(*args, **kwargs)
  File "D:\b6\mt\lib\site-packages\django\core\management\commands\runserver.py", line 133, in inner_run
    self.check(display_num_errors=True)
  File "D:\b6\mt\lib\site-packages\django\core\management\base.py", line 485, in check
    all_issues = checks.run_checks(
  File "D:\b6\mt\lib\site-packages\django\core\checks\registry.py", line 88, in run_checks
    new_errors = check(app_configs=app_configs, databases=databases)
  File "D:\b6\mt\lib\site-packages\django\core\checks\urls.py", line 14, in check_url_config
    return check_resolver(resolver)
  File "D:\b6\mt\lib\site-packages\django\core\checks\urls.py", line 24, in check_resolver
    return check_method()
  File "D:\b6\mt\lib\site-packages\django\urls\resolvers.py", line 494, in check
    for pattern in self.url_patterns:
  File "D:\b6\mt\lib\site-packages\django\utils\functional.py", line 57, in __get__
    res = instance.__dict__[self.name] = self.func(instance)
  File "D:\b6\mt\lib\site-packages\django\urls\resolvers.py", line 715, in url_patterns
    patterns = getattr(self.urlconf_module, "urlpatterns", self.urlconf_module)
  File "D:\b6\mt\lib\site-packages\django\utils\functional.py", line 57, in __get__
    res = instance.__dict__[self.name] = self.func(instance)
  File "D:\b6\mt\lib\site-packages\django\urls\resolvers.py", line 708, in urlconf_module
    return import_module(self.urlconf_name)
  File "C:\ProgramData\Anaconda3\lib\importlib\__init__.py", line 127, in import_module
    return _bootstrap._gcd_import(name[level:], package, level)
  File "<frozen importlib._bootstrap>", line 1014, in _gcd_import
  File "<frozen importlib._bootstrap>", line 991, in _find_and_load
  File "<frozen importlib._bootstrap>", line 975, in _find_and_load_unlocked
  File "<frozen importlib._bootstrap>", line 671, in _load_unlocked
  File "<frozen importlib._bootstrap_external>", line 783, in exec_module
  File "<frozen importlib._bootstrap>", line 219, in _call_with_frames_removed
  File "D:\b6\p1\p1\urls.py", line 24, in <module>
    path('m1/',views.B6),
AttributeError: module 'app2.views' has no attribute 'B6'
D:\b6\p1\p1\urls.py changed, reloading.
Watching for file changes with StatReloader
Performing system checks...

Exception in thread django-main-thread:
Traceback (most recent call last):
  File "C:\ProgramData\Anaconda3\lib\threading.py", line 932, in _bootstrap_inner
    self.run()
  File "C:\ProgramData\Anaconda3\lib\threading.py", line 870, in run
    self._target(*self._args, **self._kwargs)
  File "D:\b6\mt\lib\site-packages\django\utils\autoreload.py", line 64, in wrapper
    fn(*args, **kwargs)
  File "D:\b6\mt\lib\site-packages\django\core\management\commands\runserver.py", line 133, in inner_run
    self.check(display_num_errors=True)
  File "D:\b6\mt\lib\site-packages\django\core\management\base.py", line 485, in check
    all_issues = checks.run_checks(
  File "D:\b6\mt\lib\site-packages\django\core\checks\registry.py", line 88, in run_checks
    new_errors = check(app_configs=app_configs, databases=databases)
  File "D:\b6\mt\lib\site-packages\django\core\checks\urls.py", line 14, in check_url_config
    return check_resolver(resolver)
  File "D:\b6\mt\lib\site-packages\django\core\checks\urls.py", line 24, in check_resolver
    return check_method()
  File "D:\b6\mt\lib\site-packages\django\urls\resolvers.py", line 494, in check
    for pattern in self.url_patterns:
  File "D:\b6\mt\lib\site-packages\django\utils\functional.py", line 57, in __get__
    res = instance.__dict__[self.name] = self.func(instance)
  File "D:\b6\mt\lib\site-packages\django\urls\resolvers.py", line 715, in url_patterns
    patterns = getattr(self.urlconf_module, "urlpatterns", self.urlconf_module)
  File "D:\b6\mt\lib\site-packages\django\utils\functional.py", line 57, in __get__
    res = instance.__dict__[self.name] = self.func(instance)
  File "D:\b6\mt\lib\site-packages\django\urls\resolvers.py", line 708, in urlconf_module
    return import_module(self.urlconf_name)
  File "C:\ProgramData\Anaconda3\lib\importlib\__init__.py", line 127, in import_module
    return _bootstrap._gcd_import(name[level:], package, level)
  File "<frozen importlib._bootstrap>", line 1014, in _gcd_import
  File "<frozen importlib._bootstrap>", line 991, in _find_and_load
  File "<frozen importlib._bootstrap>", line 975, in _find_and_load_unlocked
  File "<frozen importlib._bootstrap>", line 671, in _load_unlocked
  File "<frozen importlib._bootstrap_external>", line 783, in exec_module
  File "<frozen importlib._bootstrap>", line 219, in _call_with_frames_removed
  File "D:\b6\p1\p1\urls.py", line 26, in <module>
    path('m/',m.B),
AttributeError: module 'app2.views' has no attribute 'B'
D:\b6\p1\p1\urls.py changed, reloading.
Watching for file changes with StatReloader
Performing system checks...

Exception in thread django-main-thread:
Traceback (most recent call last):
  File "C:\ProgramData\Anaconda3\lib\threading.py", line 932, in _bootstrap_inner
    self.run()
  File "C:\ProgramData\Anaconda3\lib\threading.py", line 870, in run
    self._target(*self._args, **self._kwargs)
  File "D:\b6\mt\lib\site-packages\django\utils\autoreload.py", line 64, in wrapper
    fn(*args, **kwargs)
  File "D:\b6\mt\lib\site-packages\django\core\management\commands\runserver.py", line 133, in inner_run
    self.check(display_num_errors=True)
  File "D:\b6\mt\lib\site-packages\django\core\management\base.py", line 485, in check
    all_issues = checks.run_checks(
  File "D:\b6\mt\lib\site-packages\django\core\checks\registry.py", line 88, in run_checks
    new_errors = check(app_configs=app_configs, databases=databases)
  File "D:\b6\mt\lib\site-packages\django\core\checks\urls.py", line 14, in check_url_config
    return check_resolver(resolver)
  File "D:\b6\mt\lib\site-packages\django\core\checks\urls.py", line 24, in check_resolver
    return check_method()
  File "D:\b6\mt\lib\site-packages\django\urls\resolvers.py", line 494, in check
    for pattern in self.url_patterns:
  File "D:\b6\mt\lib\site-packages\django\utils\functional.py", line 57, in __get__
    res = instance.__dict__[self.name] = self.func(instance)
  File "D:\b6\mt\lib\site-packages\django\urls\resolvers.py", line 715, in url_patterns
    patterns = getattr(self.urlconf_module, "urlpatterns", self.urlconf_module)
  File "D:\b6\mt\lib\site-packages\django\utils\functional.py", line 57, in __get__
    res = instance.__dict__[self.name] = self.func(instance)
  File "D:\b6\mt\lib\site-packages\django\urls\resolvers.py", line 708, in urlconf_module
    return import_module(self.urlconf_name)
  File "C:\ProgramData\Anaconda3\lib\importlib\__init__.py", line 127, in import_module
    return _bootstrap._gcd_import(name[level:], package, level)
  File "<frozen importlib._bootstrap>", line 1014, in _gcd_import
  File "<frozen importlib._bootstrap>", line 991, in _find_and_load
  File "<frozen importlib._bootstrap>", line 975, in _find_and_load_unlocked
  File "<frozen importlib._bootstrap>", line 671, in _load_unlocked
  File "<frozen importlib._bootstrap_external>", line 783, in exec_module
  File "<frozen importlib._bootstrap>", line 219, in _call_with_frames_removed
  File "D:\b6\p1\p1\urls.py", line 26, in <module>
    path('m/',m.B),
AttributeError: module 'app2.views' has no attribute 'B'
D:\b6\p1\app2\views.py changed, reloading.
Watching for file changes with StatReloader
Performing system checks...

System check identified no issues (0 silenced).

You have 18 unapplied migration(s). Your project may not work properly until you apply the migrations for app(s): admin, auth, contenttypes, sessions.
Run 'python manage.py migrate' to apply them.
July 02, 2025 - 10:18:16
Django version 4.2.23, using settings 'p1.settings'
Starting development server at http://127.0.0.1:7000/
Quit the server with CTRL-BREAK.

[02/Jul/2025 10:18:18] "GET / HTTP/1.1" 200 10
[02/Jul/2025 10:18:23] "GET /mt/ HTTP/1.1" 200 2
[02/Jul/2025 10:18:27] "GET /m HTTP/1.1" 301 0
[02/Jul/2025 10:18:27] "GET /m/ HTTP/1.1" 200 7
D:\b6\p1\p1\urls.py changed, reloading.
Watching for file changes with StatReloader
Performing system checks...

System check identified no issues (0 silenced).

You have 18 unapplied migration(s). Your project may not work properly until you apply the migrations for app(s): admin, auth, contenttypes, sessions.
Run 'python manage.py migrate' to apply them.
July 02, 2025 - 10:24:01
Django version 4.2.23, using settings 'p1.settings'
Starting development server at http://127.0.0.1:7000/
Quit the server with CTRL-BREAK.

D:\b6\p1\p1\urls.py changed, reloading.
Watching for file changes with StatReloader
Performing system checks...

Exception in thread django-main-thread:
Traceback (most recent call last):
  File "C:\ProgramData\Anaconda3\lib\threading.py", line 932, in _bootstrap_inner
    self.run()
  File "C:\ProgramData\Anaconda3\lib\threading.py", line 870, in run
    self._target(*self._args, **self._kwargs)
  File "D:\b6\mt\lib\site-packages\django\utils\autoreload.py", line 64, in wrapper
    fn(*args, **kwargs)
  File "D:\b6\mt\lib\site-packages\django\core\management\commands\runserver.py", line 133, in inner_run
    self.check(display_num_errors=True)
  File "D:\b6\mt\lib\site-packages\django\core\management\base.py", line 485, in check
    all_issues = checks.run_checks(
  File "D:\b6\mt\lib\site-packages\django\core\checks\registry.py", line 88, in run_checks
    new_errors = check(app_configs=app_configs, databases=databases)
  File "D:\b6\mt\lib\site-packages\django\core\checks\urls.py", line 42, in check_url_namespaces_unique
    all_namespaces = _load_all_namespaces(resolver)
  File "D:\b6\mt\lib\site-packages\django\core\checks\urls.py", line 61, in _load_all_namespaces
    url_patterns = getattr(resolver, "url_patterns", [])
  File "D:\b6\mt\lib\site-packages\django\utils\functional.py", line 57, in __get__
    res = instance.__dict__[self.name] = self.func(instance)
  File "D:\b6\mt\lib\site-packages\django\urls\resolvers.py", line 715, in url_patterns
    patterns = getattr(self.urlconf_module, "urlpatterns", self.urlconf_module)
  File "D:\b6\mt\lib\site-packages\django\utils\functional.py", line 57, in __get__
    res = instance.__dict__[self.name] = self.func(instance)
  File "D:\b6\mt\lib\site-packages\django\urls\resolvers.py", line 708, in urlconf_module
    return import_module(self.urlconf_name)
  File "C:\ProgramData\Anaconda3\lib\importlib\__init__.py", line 127, in import_module
    return _bootstrap._gcd_import(name[level:], package, level)
  File "<frozen importlib._bootstrap>", line 1014, in _gcd_import
  File "<frozen importlib._bootstrap>", line 991, in _find_and_load
  File "<frozen importlib._bootstrap>", line 975, in _find_and_load_unlocked
  File "<frozen importlib._bootstrap>", line 671, in _load_unlocked
  File "<frozen importlib._bootstrap_external>", line 779, in exec_module
  File "<frozen importlib._bootstrap_external>", line 916, in get_code
  File "<frozen importlib._bootstrap_external>", line 846, in source_to_code
  File "<frozen importlib._bootstrap>", line 219, in _call_with_frames_removed
  File "D:\b6\p1\p1\urls.py", line 25
    path('app2/',include(app2.urls))
    ^
SyntaxError: invalid syntax
D:\b6\p1\p1\urls.py changed, reloading.
Watching for file changes with StatReloader
Performing system checks...

Exception in thread django-main-thread:
Traceback (most recent call last):
  File "C:\ProgramData\Anaconda3\lib\threading.py", line 932, in _bootstrap_inner
    self.run()
  File "C:\ProgramData\Anaconda3\lib\threading.py", line 870, in run
    self._target(*self._args, **self._kwargs)
  File "D:\b6\mt\lib\site-packages\django\utils\autoreload.py", line 64, in wrapper
    fn(*args, **kwargs)
  File "D:\b6\mt\lib\site-packages\django\core\management\commands\runserver.py", line 133, in inner_run
    self.check(display_num_errors=True)
  File "D:\b6\mt\lib\site-packages\django\core\management\base.py", line 485, in check
    all_issues = checks.run_checks(
  File "D:\b6\mt\lib\site-packages\django\core\checks\registry.py", line 88, in run_checks
    new_errors = check(app_configs=app_configs, databases=databases)
  File "D:\b6\mt\lib\site-packages\django\core\checks\urls.py", line 42, in check_url_namespaces_unique
    all_namespaces = _load_all_namespaces(resolver)
  File "D:\b6\mt\lib\site-packages\django\core\checks\urls.py", line 61, in _load_all_namespaces
    url_patterns = getattr(resolver, "url_patterns", [])
  File "D:\b6\mt\lib\site-packages\django\utils\functional.py", line 57, in __get__
    res = instance.__dict__[self.name] = self.func(instance)
  File "D:\b6\mt\lib\site-packages\django\urls\resolvers.py", line 715, in url_patterns
    patterns = getattr(self.urlconf_module, "urlpatterns", self.urlconf_module)
  File "D:\b6\mt\lib\site-packages\django\utils\functional.py", line 57, in __get__
    res = instance.__dict__[self.name] = self.func(instance)
  File "D:\b6\mt\lib\site-packages\django\urls\resolvers.py", line 708, in urlconf_module
    return import_module(self.urlconf_name)
  File "C:\ProgramData\Anaconda3\lib\importlib\__init__.py", line 127, in import_module
    return _bootstrap._gcd_import(name[level:], package, level)
  File "<frozen importlib._bootstrap>", line 1014, in _gcd_import
  File "<frozen importlib._bootstrap>", line 991, in _find_and_load
  File "<frozen importlib._bootstrap>", line 975, in _find_and_load_unlocked
  File "<frozen importlib._bootstrap>", line 671, in _load_unlocked
  File "<frozen importlib._bootstrap_external>", line 779, in exec_module
  File "<frozen importlib._bootstrap_external>", line 916, in get_code
  File "<frozen importlib._bootstrap_external>", line 846, in source_to_code
  File "<frozen importlib._bootstrap>", line 219, in _call_with_frames_removed
  File "D:\b6\p1\p1\urls.py", line 25
    path('app2/',include(app2.urls))
    ^
SyntaxError: invalid syntax
D:\b6\p1\p1\urls.py changed, reloading.
Watching for file changes with StatReloader
Performing system checks...

Exception in thread django-main-thread:
Traceback (most recent call last):
  File "C:\ProgramData\Anaconda3\lib\threading.py", line 932, in _bootstrap_inner
    self.run()
  File "C:\ProgramData\Anaconda3\lib\threading.py", line 870, in run
    self._target(*self._args, **self._kwargs)
  File "D:\b6\mt\lib\site-packages\django\utils\autoreload.py", line 64, in wrapper
    fn(*args, **kwargs)
  File "D:\b6\mt\lib\site-packages\django\core\management\commands\runserver.py", line 133, in inner_run
    self.check(display_num_errors=True)
  File "D:\b6\mt\lib\site-packages\django\core\management\base.py", line 485, in check
    all_issues = checks.run_checks(
  File "D:\b6\mt\lib\site-packages\django\core\checks\registry.py", line 88, in run_checks
    new_errors = check(app_configs=app_configs, databases=databases)
  File "D:\b6\mt\lib\site-packages\django\core\checks\urls.py", line 42, in check_url_namespaces_unique
    all_namespaces = _load_all_namespaces(resolver)
  File "D:\b6\mt\lib\site-packages\django\core\checks\urls.py", line 61, in _load_all_namespaces
    url_patterns = getattr(resolver, "url_patterns", [])
  File "D:\b6\mt\lib\site-packages\django\utils\functional.py", line 57, in __get__
    res = instance.__dict__[self.name] = self.func(instance)
  File "D:\b6\mt\lib\site-packages\django\urls\resolvers.py", line 715, in url_patterns
    patterns = getattr(self.urlconf_module, "urlpatterns", self.urlconf_module)
  File "D:\b6\mt\lib\site-packages\django\utils\functional.py", line 57, in __get__
    res = instance.__dict__[self.name] = self.func(instance)
  File "D:\b6\mt\lib\site-packages\django\urls\resolvers.py", line 708, in urlconf_module
    return import_module(self.urlconf_name)
  File "C:\ProgramData\Anaconda3\lib\importlib\__init__.py", line 127, in import_module
    return _bootstrap._gcd_import(name[level:], package, level)
  File "<frozen importlib._bootstrap>", line 1014, in _gcd_import
  File "<frozen importlib._bootstrap>", line 991, in _find_and_load
  File "<frozen importlib._bootstrap>", line 975, in _find_and_load_unlocked
  File "<frozen importlib._bootstrap>", line 671, in _load_unlocked
  File "<frozen importlib._bootstrap_external>", line 783, in exec_module
  File "<frozen importlib._bootstrap>", line 219, in _call_with_frames_removed
  File "D:\b6\p1\p1\urls.py", line 24, in <module>
    path('app1/',include(app1.urls)),
NameError: name 'app1' is not defined
D:\b6\p1\p1\urls.py changed, reloading.
Watching for file changes with StatReloader
Performing system checks...

Exception in thread django-main-thread:
Traceback (most recent call last):
  File "C:\ProgramData\Anaconda3\lib\threading.py", line 932, in _bootstrap_inner
    self.run()
  File "C:\ProgramData\Anaconda3\lib\threading.py", line 870, in run
    self._target(*self._args, **self._kwargs)
  File "D:\b6\mt\lib\site-packages\django\utils\autoreload.py", line 64, in wrapper
    fn(*args, **kwargs)
  File "D:\b6\mt\lib\site-packages\django\core\management\commands\runserver.py", line 133, in inner_run
    self.check(display_num_errors=True)
  File "D:\b6\mt\lib\site-packages\django\core\management\base.py", line 485, in check
    all_issues = checks.run_checks(
  File "D:\b6\mt\lib\site-packages\django\core\checks\registry.py", line 88, in run_checks
    new_errors = check(app_configs=app_configs, databases=databases)
  File "D:\b6\mt\lib\site-packages\django\core\checks\urls.py", line 42, in check_url_namespaces_unique
    all_namespaces = _load_all_namespaces(resolver)
  File "D:\b6\mt\lib\site-packages\django\core\checks\urls.py", line 61, in _load_all_namespaces
    url_patterns = getattr(resolver, "url_patterns", [])
  File "D:\b6\mt\lib\site-packages\django\utils\functional.py", line 57, in __get__
    res = instance.__dict__[self.name] = self.func(instance)
  File "D:\b6\mt\lib\site-packages\django\urls\resolvers.py", line 715, in url_patterns
    patterns = getattr(self.urlconf_module, "urlpatterns", self.urlconf_module)
  File "D:\b6\mt\lib\site-packages\django\utils\functional.py", line 57, in __get__
    res = instance.__dict__[self.name] = self.func(instance)
  File "D:\b6\mt\lib\site-packages\django\urls\resolvers.py", line 708, in urlconf_module
    return import_module(self.urlconf_name)
  File "C:\ProgramData\Anaconda3\lib\importlib\__init__.py", line 127, in import_module
    return _bootstrap._gcd_import(name[level:], package, level)
  File "<frozen importlib._bootstrap>", line 1014, in _gcd_import
  File "<frozen importlib._bootstrap>", line 991, in _find_and_load
  File "<frozen importlib._bootstrap>", line 975, in _find_and_load_unlocked
  File "<frozen importlib._bootstrap>", line 671, in _load_unlocked
  File "<frozen importlib._bootstrap_external>", line 783, in exec_module
  File "<frozen importlib._bootstrap>", line 219, in _call_with_frames_removed
  File "D:\b6\p1\p1\urls.py", line 24, in <module>
    path('app1/',include(app1.urls)),
NameError: name 'app1' is not defined
D:\b6\p1\p1\urls.py changed, reloading.
Watching for file changes with StatReloader
Performing system checks...

Exception in thread django-main-thread:
Traceback (most recent call last):
  File "C:\ProgramData\Anaconda3\lib\threading.py", line 932, in _bootstrap_inner
    self.run()
  File "C:\ProgramData\Anaconda3\lib\threading.py", line 870, in run
    self._target(*self._args, **self._kwargs)
  File "D:\b6\mt\lib\site-packages\django\utils\autoreload.py", line 64, in wrapper
    fn(*args, **kwargs)
  File "D:\b6\mt\lib\site-packages\django\core\management\commands\runserver.py", line 133, in inner_run
    self.check(display_num_errors=True)
  File "D:\b6\mt\lib\site-packages\django\core\management\base.py", line 485, in check
    all_issues = checks.run_checks(
  File "D:\b6\mt\lib\site-packages\django\core\checks\registry.py", line 88, in run_checks
    new_errors = check(app_configs=app_configs, databases=databases)
  File "D:\b6\mt\lib\site-packages\django\core\checks\urls.py", line 42, in check_url_namespaces_unique
    all_namespaces = _load_all_namespaces(resolver)
  File "D:\b6\mt\lib\site-packages\django\core\checks\urls.py", line 61, in _load_all_namespaces
    url_patterns = getattr(resolver, "url_patterns", [])
  File "D:\b6\mt\lib\site-packages\django\utils\functional.py", line 57, in __get__
    res = instance.__dict__[self.name] = self.func(instance)
  File "D:\b6\mt\lib\site-packages\django\urls\resolvers.py", line 715, in url_patterns
    patterns = getattr(self.urlconf_module, "urlpatterns", self.urlconf_module)
  File "D:\b6\mt\lib\site-packages\django\utils\functional.py", line 57, in __get__
    res = instance.__dict__[self.name] = self.func(instance)
  File "D:\b6\mt\lib\site-packages\django\urls\resolvers.py", line 708, in urlconf_module
    return import_module(self.urlconf_name)
  File "C:\ProgramData\Anaconda3\lib\importlib\__init__.py", line 127, in import_module
    return _bootstrap._gcd_import(name[level:], package, level)
  File "<frozen importlib._bootstrap>", line 1014, in _gcd_import
  File "<frozen importlib._bootstrap>", line 991, in _find_and_load
  File "<frozen importlib._bootstrap>", line 975, in _find_and_load_unlocked
  File "<frozen importlib._bootstrap>", line 671, in _load_unlocked
  File "<frozen importlib._bootstrap_external>", line 783, in exec_module
  File "<frozen importlib._bootstrap>", line 219, in _call_with_frames_removed
  File "D:\b6\p1\p1\urls.py", line 24, in <module>
    path('app1/',include(app1.urls)),
NameError: name 'app1' is not defined
D:\b6\p1\p1\urls.py changed, reloading.
Watching for file changes with StatReloader
Performing system checks...

Exception in thread django-main-thread:
Traceback (most recent call last):
  File "C:\ProgramData\Anaconda3\lib\threading.py", line 932, in _bootstrap_inner
    self.run()
  File "C:\ProgramData\Anaconda3\lib\threading.py", line 870, in run
    self._target(*self._args, **self._kwargs)
  File "D:\b6\mt\lib\site-packages\django\utils\autoreload.py", line 64, in wrapper
    fn(*args, **kwargs)
  File "D:\b6\mt\lib\site-packages\django\core\management\commands\runserver.py", line 133, in inner_run
    self.check(display_num_errors=True)
  File "D:\b6\mt\lib\site-packages\django\core\management\base.py", line 485, in check
    all_issues = checks.run_checks(
  File "D:\b6\mt\lib\site-packages\django\core\checks\registry.py", line 88, in run_checks
    new_errors = check(app_configs=app_configs, databases=databases)
  File "D:\b6\mt\lib\site-packages\django\core\checks\urls.py", line 42, in check_url_namespaces_unique
    all_namespaces = _load_all_namespaces(resolver)
  File "D:\b6\mt\lib\site-packages\django\core\checks\urls.py", line 61, in _load_all_namespaces
    url_patterns = getattr(resolver, "url_patterns", [])
  File "D:\b6\mt\lib\site-packages\django\utils\functional.py", line 57, in __get__
    res = instance.__dict__[self.name] = self.func(instance)
  File "D:\b6\mt\lib\site-packages\django\urls\resolvers.py", line 715, in url_patterns
    patterns = getattr(self.urlconf_module, "urlpatterns", self.urlconf_module)
  File "D:\b6\mt\lib\site-packages\django\utils\functional.py", line 57, in __get__
    res = instance.__dict__[self.name] = self.func(instance)
  File "D:\b6\mt\lib\site-packages\django\urls\resolvers.py", line 708, in urlconf_module
    return import_module(self.urlconf_name)
  File "C:\ProgramData\Anaconda3\lib\importlib\__init__.py", line 127, in import_module
    return _bootstrap._gcd_import(name[level:], package, level)
  File "<frozen importlib._bootstrap>", line 1014, in _gcd_import
  File "<frozen importlib._bootstrap>", line 991, in _find_and_load
  File "<frozen importlib._bootstrap>", line 975, in _find_and_load_unlocked
  File "<frozen importlib._bootstrap>", line 671, in _load_unlocked
  File "<frozen importlib._bootstrap_external>", line 783, in exec_module
  File "<frozen importlib._bootstrap>", line 219, in _call_with_frames_removed
  File "D:\b6\p1\p1\urls.py", line 23, in <module>
    path('app1/',include(app1.urls)),
NameError: name 'app1' is not defined
D:\b6\p1\p1\urls.py changed, reloading.
Watching for file changes with StatReloader
Performing system checks...

System check identified no issues (0 silenced).

You have 18 unapplied migration(s). Your project may not work properly until you apply the migrations for app(s): admin, auth, contenttypes, sessions.
Run 'python manage.py migrate' to apply them.
July 02, 2025 - 10:29:32
Django version 4.2.23, using settings 'p1.settings'
Starting development server at http://127.0.0.1:7000/
Quit the server with CTRL-BREAK.

Not Found: /
[02/Jul/2025 10:29:35] "GET / HTTP/1.1" 404 2265
[02/Jul/2025 10:29:44] "GET /app1 HTTP/1.1" 301 0
[02/Jul/2025 10:29:44] "GET /app1/ HTTP/1.1" 200 10
Not Found: /app2/
[02/Jul/2025 10:29:50] "GET /app2/ HTTP/1.1" 404 2347
D:\b6\p1\app2\urls.py changed, reloading.
Watching for file changes with StatReloader
Performing system checks...

System check identified no issues (0 silenced).

You have 18 unapplied migration(s). Your project may not work properly until you apply the migrations for app(s): admin, auth, contenttypes, sessions.
Run 'python manage.py migrate' to apply them.
July 02, 2025 - 10:30:21
Django version 4.2.23, using settings 'p1.settings'
Starting development server at http://127.0.0.1:7000/
Quit the server with CTRL-BREAK.

Not Found: /app2/
[02/Jul/2025 10:30:24] "GET /app2/ HTTP/1.1" 404 2347
Not Found: /app2/
[02/Jul/2025 10:30:25] "GET /app2/ HTTP/1.1" 404 2347
Not Found: /app2/
[02/Jul/2025 10:30:25] "GET /app2/ HTTP/1.1" 404 2347
Not Found: /app2/
[02/Jul/2025 10:30:25] "GET /app2/ HTTP/1.1" 404 2347
[02/Jul/2025 10:30:41] "GET /app2/m HTTP/1.1" 301 0
[02/Jul/2025 10:30:41] "GET /app2/m/ HTTP/1.1" 200 7






install lj and lju in setting.py
